Workbook

Sheet Summary Report
A1: HARSHA TEA HOUSE - FINANCIAL MODEL SUMMARY REPORT
A3: Harsha Tea House is a premium neighbourhood tea shop operating a single outlet in Coimbatore.
A4: The business primarily generates revenue through the sale of tea, coffee, snacks and beverages.
A5: The model assumes stable customer growth driven by improved service quality,
A6: operational efficiency and periodic capital expenditure on equipment and store improvements.
A8: BUSINESS INFORMATION
A9: Particulars | B9: Value
A10: Company Name | B10: Harsha Tea House
A11: Industry | B11: Food & Beverage (Tea Café)
A12: Business Type | B12: Single Outlet Premium Tea Shop
A13: Forecast Period | B13: FY2025 - FY2029
A14: Historical Period | B14: FY2022 - FY2024
A15: Currency | B15: INR (₹)
A16: Valuation Method | B16: Discounted Cash Flow (FCFF)
A17: Valuation Date | B17: 45747
A19: EXECUTIVE SUMMARY
A20: Metric | B20: Value
A21: Enterprise Value | B21: ='Detailed Report'!$E$10 -> 11003425
A22: Equity Value | B22: ='Detailed Report'!$E$14 -> 11093425
A23: Net Debt | B23: ='Detailed Report'!$E$11 -> 80000
A24: WACC | B24: =Assumptions!C68 -> 12%
A25: Terminal Growth Rate | B25: =Assumptions!C69 -> 4%
A27: FINANCIAL PERFORMANCE
A28: Metric | B28: FY25 | C28: FY26 | D28: FY27 | E28: FY28 | F28: FY29
A29: Revenue | B29: ='Forecast IS'!B4 -> 4860000 | C29: ='Forecast IS'!C4 -> 5458752 | D29: ='Forecast IS'!D4 -> 6131270.2 | E29: ='Forecast IS'!E4 -> 6886642.7 | F29: ='Forecast IS'!F4 -> 7735077.1
A30: Revenue Growth % | B30: 0 | C30: ='Forecast IS'!C5 -> 0.1232 | D30: ='Forecast IS'!D5 -> 0.1232 | E30: ='Forecast IS'!E5 -> 0.1232 | F30: ='Forecast IS'!F5 -> 0.1232
A31: Gross Profit | B31: ='Forecast IS'!B8 -> 3273696 | C31: ='Forecast IS'!C8 -> 3677015.3 | D31: ='Forecast IS'!D8 -> 4168509.1 | E31: ='Forecast IS'!E8 -> 4724465.1 | F31: ='Forecast IS'!F8 -> 5353222.3
A32: Gross Margin % | B32: ='Forecast IS'!B9 -> 0.6736 | C32: ='Forecast IS'!C9 -> 0.6736 | D32: ='Forecast IS'!D9 -> 0.67987692 | E32: ='Forecast IS'!E9 -> 0.68603314 | F32: ='Forecast IS'!F9 -> 0.69207096
A33: EBITDA | B33: ='Forecast IS'!B12 -> 493896 | C33: ='Forecast IS'!C12 -> 700752.72 | D33: ='Forecast IS'!D12 -> 980901.97 | E33: ='Forecast IS'!E12 -> 1309425.8 | F33: ='Forecast IS'!F12 -> 1693353.4
A34: EBITDA Margin % | B34: ='Forecast IS'!B13 -> 0.10162469 | C34: ='Forecast IS'!C13 -> 0.12837233 | D34: ='Forecast IS'!D13 -> 0.15998348 | E34: ='Forecast IS'!E13 -> 0.19013993 | F34: ='Forecast IS'!F13 -> 0.21891875
A35: EBIT | B35: ='Forecast IS'!B16 -> 446396 | C35: ='Forecast IS'!C16 -> 648002.72 | D35: ='Forecast IS'!D16 -> 923426.97 | E35: ='Forecast IS'!E16 -> 1247698.3 | F35: ='Forecast IS'!F16 -> 1627798.6
A36: EBIT Margin % | B36: ='Forecast IS'!B17 -> 0.091851029 | C36: ='Forecast IS'!C17 -> 0.11870895 | D36: ='Forecast IS'!D17 -> 0.15060941 | E36: ='Forecast IS'!E17 -> 0.18117657 | F36: ='Forecast IS'!F17 -> 0.21044375
A37: Net Profit | B37: ='Forecast IS'!B24 -> 300297 | C37: ='Forecast IS'!C24 -> 460502.04 | D37: ='Forecast IS'!D24 -> 676070.23 | E37: ='Forecast IS'!E24 -> 928273.72 | F37: ='Forecast IS'!F24 -> 1220849
A38: Net Profit Margin % | B38: ='Forecast IS'!B25 -> 0.061789506 | C38: ='Forecast IS'!C25 -> 0.084360315 | D38: ='Forecast IS'!D25 -> 0.11026593 | E38: ='Forecast IS'!E25 -> 0.13479336 | F38: ='Forecast IS'!F25 -> 0.15783281
A40: CASH FLOW SUMMARY
A41: Metric | B41: FY25 | C41: FY26 | D41: FY27 | E41: FY28 | F41: FY29
A42: Operating Cash Flow | B42: ='Forecast CF'!B7 -> 401393 | C42: ='Forecast CF'!C7 -> 516405.46 | D42: ='Forecast CF'!D7 -> 735483.59 | E42: ='Forecast CF'!E7 -> 992015.47 | F42: ='Forecast CF'!F7 -> 1288486.7
A43: Investing Cash Flow | B43: ='Forecast CF'!B8 -> -100000 | C43: ='Forecast CF'!C8 -> -100000 | D43: ='Forecast CF'!D8 -> -100000 | E43: ='Forecast CF'!E8 -> -100000 | F43: ='Forecast CF'!F8 -> -100000
A44: Financing Cash Flow | B44: =SUM('Forecast CF'!B9:B10) -> 319940.6 | C44: =SUM('Forecast CF'!C9:C10) -> -212100.41 | D44: =SUM('Forecast CF'!D9:D10) -> -255214.05 | E44: =SUM('Forecast CF'!E9:E10) -> -305654.74 | F44: =SUM('Forecast CF'!F9:F10) -> -344169.79
A45: Free Cash Flow to Firm (FCFF) | B45: ='DCF Valuation'!B11 -> 405893 | C45: ='DCF Valuation'!C11 -> 526905.46 | D45: ='DCF Valuation'!D11 -> 731983.59 | E45: ='DCF Valuation'!E11 -> 984515.47 | F45: ='DCF Valuation'!F11 -> 1268486.7
...

Sheet Detailed Report
C3: Valuation of the Business
C4: (figures in rupees)
D6: Particulars | E6: Amount
D7: Sum of PVFCFF | E7: =SUM('DCF Valuation'!B14:F14) -> 2648912.5
D8: Terminal Value | E8: ='DCF Valuation'!F11*1.04/(12%-4%) -> 16490327
D9: PV of TV | E9: =E8*'DCF Valuation'!G12 -> 8354512.6
D10: Enterprise Value | E10: =E9+E7 -> 11003425
D11: Debt | E11: ='Historical FS'!D24 -> 80000
D12: Cash | E12: ='Historical FS'!D18 -> 170000
D14: Equity Value | E14: =E10-E11+E12 -> 11093425

Sheet Business Summary
B1: Business Summary
B3: Harsha Tea House is a premium neighbourhood tea shop operating a single outlet in Coimbatore.
B4: The business primarily generates revenue through the sale of tea, coffee, snacks and beverages.
B5: The model assumes stable customer growth driven by improved service quality,
B6: operational efficiency and periodic capital expenditure on equipment and store improvements.
B8: Section | C8: Details
B9: Company Name | C9: Harsha Tea House
B10: Industry | C10: Food & Beverage (Quick Service Restaurant - Tea Café)
B11: Business Type | C11: Single Outlet Premium Tea Shop
B12: Business Model | C12: Retail sale of tea, coffee, snacks and light refreshments through dine-in and takeaway
B13: Location | C13: Coimbatore, Tamil Nadu (Assumed)
B14: Forecast Period | C14: FY2025 – FY2029
B15: Currency | C15: Indian Rupees (₹)
B16: Financial Year | C16: April – March
B17: Valuation Date | C17: 45747
B18: Valuation Method | C18: Discounted Cash Flow (FCFF)
B19: Purpose of Model | C19: Forecast financial performance and estimate enterprise & equity value
B20: Historical Period | C20: FY2022 – FY2024
B21: Projected Period | C21: FY2025 – FY2029

Sheet Assumptions
A1: Assumptions
A3: Category | B3: Assumption | C3: Value
A4: GENERAL | B4: Opening Year | C4: FY2025
A5: GENERAL | B5: Forecast Period (Years) | C5: 5
A6: GENERAL | B6: Working Days | C6: 360
A7: GENERAL | B7: Inflation | C7: 5%
A9: REVENUE | B9: Customers/Day | C9: 180
A10: REVENUE | B10: Customer Growth | C10: 8%
A11: REVENUE | B11: Average Bill | C11: 75
A12: REVENUE | B12: Price Growth | C12: 4%
A13: REVENUE | B13: Revenue Growth | C13: 12%
A14: REVENUE | B14: Days operating | C14: 360
A16: COGS | B16: Tea Powder/Customer | C16: 4
A17: COGS | B17: Milk/Customer | C17: 8
A18: COGS | B18: Sugar/Customer | C18: 2
A19: COGS | B19: Spices/Customer | C19: 2
A20: COGS | B20: Packaging/Customer | C20: 3
A21: COGS | B21: Snacks Ingredients/Customer | C21: 5
A22: COGS | B22: Wastage (%) | C22: 2%
A23: COGS | B23: Inflation | C23: 0.04
A25: PAYROLL | B25: Manager Salary | C25: 30000
A26: PAYROLL | B26: Cashier Salary | C26: 18000
A27: PAYROLL | B27: Tea Master Salary | C27: 20000
A28: PAYROLL | B28: Helper Salary | C28: 15000
A29: PAYROLL | B29: Cleaner Salary | C29: 12000
A30: PAYROLL | B30: Managers | C30: 1
A31: PAYROLL | B31: Cashiers | C31: 1
A32: PAYROLL | B32: Tea Masters | C32: 2
A33: PAYROLL | B33: Helpers | C33: 2
A34: PAYROLL | B34: Cleaners | C34: 1
A35: PAYROLL | B35: Salary Increment | C35: 8%
A37: OPEX | B37: Annual Rent | C37: 600000
A38: OPEX | B38: Electricity | C38: 200000
A39: OPEX | B39: LPG | C39: 60000
A40: OPEX | B40: Water | C40: 36000
A41: OPEX | B41: Internet | C41: 18000
A42: OPEX | B42: Marketing | C42: 3% Revenue
A43: OPEX | B43: Repairs | C43: 50000
A44: OPEX | B44: Insurance | C44: 24000
A45: OPEX | B45: Office Expense | C45: 36000
...

Sheet Forecast IS
A1: Forecasted Income Statement
A2: (figures in rupees)
A3: Line Item | B3: FY25 | C3: FY26 | D3: FY27 | E3: FY28 | F3: FY29
A4: ='Historical FS'!A5 -> Revenue | B4: ='Revenue Schedule'!B6 -> 4860000 | C4: ='Revenue Schedule'!C6 -> 5458752 | D4: ='Revenue Schedule'!D6 -> 6131270.2 | E4: ='Revenue Schedule'!E6 -> 6886642.7 | F4: ='Revenue Schedule'!F6 -> 7735077.1
A5: % Revenue Growth | C5: =(C4-B4)/B4 -> 0.1232 | D5: =(D4-C4)/C4 -> 0.1232 | E5: =(E4-D4)/D4 -> 0.1232 | F5: =(F4-E4)/E4 -> 0.1232
A6: ='Historical FS'!A6 -> COGS | B6: ='COGS Schedule'!B15 -> 1586304 | C6: ='COGS Schedule'!C15 -> 1781736.7 | D6: ='COGS Schedule'!D15 -> 1962761.1 | E6: ='COGS Schedule'!E15 -> 2162177.6 | F6: ='COGS Schedule'!F15 -> 2381854.9
A7: % COGS Growth | C7: =(C6-B6)/B6 -> 0.1232 | D7: =(D6-C6)/C6 -> 0.1016 | E7: =(E6-D6)/D6 -> 0.1016 | F7: =(F6-E6)/E6 -> 0.1016
A8: ='Historical FS'!A7 -> Gross Profit | B8: =B4-B6 -> 3273696 | C8: =C4-C6 -> 3677015.3 | D8: =D4-D6 -> 4168509.1 | E8: =E4-E6 -> 4724465.1 | F8: =F4-F6 -> 5353222.3
A9: % Gross Profit Margin | B9: =B8/B4 -> 0.6736 | C9: =C8/C4 -> 0.6736 | D9: =D8/D4 -> 0.67987692 | E9: =E8/E4 -> 0.68603314 | F9: =F8/F4 -> 0.69207096
A10: Operating Expenses (including Payroll) | B10: ='Operating Expenses'!B15+Payroll!D10 -> 2779800 | C10: ='Operating Expenses'!C15+Payroll!E10 -> 2976262.6 | D10: ='Operating Expenses'!D15+Payroll!F10 -> 3187607.1 | E10: ='Operating Expenses'!E15+Payroll!G10 -> 3415039.3 | F10: ='Operating Expenses'!F15+Payroll!H10 -> 3659868.8
A11: % Operating Expenses Growth | C11: =(C10-B10)/B10 -> 0.07067507 | D11: =(D10-C10)/C10 -> 0.071010048 | E11: =(E10-D10)/D10 -> 0.071348864 | F11: =(F10-E10)/E10 -> 0.071691578
A12: ='Historical FS'!A9 -> EBITDA | B12: =B8-B10-B11 -> 493896 | C12: =C8-C10-C11 -> 700752.72 | D12: =D8-D10-D11 -> 980901.97 | E12: =E8-E10-E11 -> 1309425.8 | F12: =F8-F10-F11 -> 1693353.4
A13: % EBITDA Margin | B13: =B12/B4 -> 0.10162469 | C13: =C12/C4 -> 0.12837233 | D13: =D12/D4 -> 0.15998348 | E13: =E12/E4 -> 0.19013993 | F13: =F12/F4 -> 0.21891875
A14: ='Historical FS'!A10 -> Depreciation | B14: =Depreciation!B6 -> 47500 | C14: =Depreciation!C6 -> 52750 | D14: =Depreciation!D6 -> 57475 | E14: =Depreciation!E6 -> 61727.5 | F14: =Depreciation!F6 -> 65554.75
A15: % of Revenue | B15: =B14/B4 -> 0.0097736626 | C15: =C14/C4 -> 0.0096633809 | D15: =D14/D4 -> 0.0093740771 | E15: =E14/E4 -> 0.0089633661 | F15: =F14/F4 -> 0.0084749963
A16: ='Historical FS'!A11 -> EBIT | B16: =B12-B14 -> 446396 | C16: =C12-C14 -> 648002.72 | D16: =D12-D14 -> 923426.97 | E16: =E12-E14 -> 1247698.3 | F16: =F12-F14 -> 1627798.6
A17: % EBIT Margin | B17: =B16/B4 -> 0.091851029 | C17: =C16/C4 -> 0.11870895 | D17: =D16/D4 -> 0.15060941 | E17: =E16/E4 -> 0.18117657 | F17: =F16/F4 -> 0.21044375
A18: ='Historical FS'!A12 -> Interest | B18: =Debt!B16 -> 46000 | C18: =Debt!C16 -> 34000 | D18: =Debt!D16 -> 22000 | E18: =Debt!E16 -> 10000 | F18: =Debt!F16 -> 0
A19: % of Revenue | B19: =B18/B4 -> 0.0094650206 | C19: =C18/C4 -> 0.0062285299 | D19: =D18/D4 -> 0.0035881635 | E19: =E18/E4 -> 0.0014520864 | F19: =Debt!F17 -> 0
A20: ='Historical FS'!A13 -> PBT | B20: =B16-B18 -> 400396 | C20: =C16-C18 -> 614002.72 | D20: =D16-D18 -> 901426.97 | E20: =E16-E18 -> 1237698.3 | F20: =F16-F18 -> 1627798.6
A21: % PBT Margin | B21: =B20/B4 -> 0.082386008 | C21: =C20/C4 -> 0.11248042 | D21: =D20/D4 -> 0.14702124 | E21: =E20/E4 -> 0.17972448 | F21: =F20/F4 -> 0.21044375
A22: ='Historical FS'!A14 -> Tax | B22: =B20*25% -> 100099 | C22: =C20*25% -> 153500.68 | D22: =D20*25% -> 225356.74 | E22: =E20*25% -> 309424.57 | F22: =F20*25% -> 406949.66
A23: % of Revenue | B23: =B22/B4 -> 0.020596502 | C23: =C22/C4 -> 0.028120105 | D23: =D22/D4 -> 0.036755311 | E23: =E22/E4 -> 0.04493112 | F23: =F22/F4 -> 0.052610937
A24: ='Historical FS'!A15 -> Net Income | B24: =B20-B22 -> 300297 | C24: =C20-C22 -> 460502.04 | D24: =D20-D22 -> 676070.23 | E24: =E20-E22 -> 928273.72 | F24: =F20-F22 -> 1220849
A25: % PAT Margin | B25: =B24/B4 -> 0.061789506 | C25: =C24/C4 -> 0.084360315 | D25: =D24/D4 -> 0.11026593 | E25: =E24/E4 -> 0.13479336 | F25: =F24/F4 -> 0.15783281

Sheet Forecast BS
A1: Forecasted Balance Sheet
A3: Line Item | B3: FY25 | C3: FY26 | D3: FY27 | E3: FY28 | F3: FY29
A4: ='Historical FS'!A18 -> Cash | B4: ='Historical FS'!D18+'Forecast CF'!B11 -> 791333.6 | C4: =B4+'Forecast CF'!C11 -> 995638.66 | D4: =C4+'Forecast CF'!D11 -> 1375908.2 | E4: =D4+'Forecast CF'!E11 -> 1962268.9 | F4: =E4+'Forecast CF'!F11 -> 2806585.8
A5: ='Historical FS'!A19 -> AR | B5: ='Working Capital'!B4 -> 40500 | C5: ='Working Capital'!C4 -> 45489.6 | D5: ='Working Capital'!D4 -> 51093.919 | E5: ='Working Capital'!E4 -> 57388.69 | F5: ='Working Capital'!F4 -> 64458.976
A6: ='Historical FS'!A20 -> Inventory | B6: ='Working Capital'!B5 -> 66096 | C6: ='Working Capital'!C5 -> 74239.027 | D6: ='Working Capital'!D5 -> 81781.712 | E6: ='Working Capital'!E5 -> 90090.734 | F6: ='Working Capital'!F5 -> 99243.953
A7: ='Historical FS'!A21 -> Net PPE | B7: =Depreciation!B7 -> 427500 | C7: =Depreciation!C7 -> 474750 | D7: =Depreciation!D7 -> 517275 | E7: =Depreciation!E7 -> 555547.5 | F7: =Depreciation!F7 -> 589992.75
A8: ='Historical FS'!A22 -> Total Assets | B8: =SUM(B4:B7) -> 1325429.6 | C8: =SUM(C4:C7) -> 1590117.3 | D8: =SUM(D4:D7) -> 2026058.8 | E8: =SUM(E4:E7) -> 2665295.9 | F8: =SUM(F4:F7) -> 3560281.5
A10: ='Historical FS'!A23 -> AP | B10: ='Working Capital'!B6 -> 132192 | C10: ='Working Capital'!C6 -> 148478.05 | D10: ='Working Capital'!D6 -> 163563.42 | E10: ='Working Capital'!E6 -> 180181.47 | F10: ='Working Capital'!F6 -> 198487.91
A11: ='Historical FS'!A24 -> Debt | B11: =Debt!B17 -> 460000 | C11: =Debt!C17 -> 340000 | D11: =Debt!D17 -> 220000 | E11: =Debt!E17 -> 100000 | F11: =Debt!F17 -> 0
A12: ='Historical FS'!A25 -> Owner Equity | B12: =Equity!B8 -> 733237.6 | C12: =Equity!C8 -> 1101639.2 | D12: =Equity!D8 -> 1642495.4 | E12: =Equity!E8 -> 2385114.4 | F12: =Equity!F8 -> 3361793.6
A13: ='Historical FS'!A26 -> Total L+E | B13: =SUM(B10:B12) -> 1325429.6 | C13: =SUM(C10:C12) -> 1590117.3 | D13: =SUM(D10:D12) -> 2026058.8 | E13: =SUM(E10:E12) -> 2665295.9 | F13: =SUM(F10:F12) -> 3560281.5
B15: =B8-B13 -> 0 | C15: =C8-C13 -> 0 | D15: =D8-D13 -> 0 | E15: =E8-E13 -> 0 | F15: =F8-F13 -> 0

Sheet Forecast CF
A1: Forecasted Cashflow Statement
A3: Line Item | B3: FY25 | C3: FY26 | D3: FY27 | E3: FY28 | F3: FY29
A4: ='Historical FS'!A29 -> Net Income | B4: ='Forecast IS'!B24 -> 300297 | C4: ='Forecast IS'!C24 -> 460502.04 | D4: ='Forecast IS'!D24 -> 676070.23 | E4: ='Forecast IS'!E24 -> 928273.72 | F4: ='Forecast IS'!F24 -> 1220849
A5: ='Historical FS'!A30 -> Depreciation | B5: =Depreciation!B6 -> 47500 | C5: =Depreciation!C6 -> 52750 | D5: =Depreciation!D6 -> 57475 | E5: =Depreciation!E6 -> 61727.5 | F5: =Depreciation!F6 -> 65554.75
A6: ='Historical FS'!A31 -> Working Capital Change | B6: =-'Working Capital'!B9 -> 53596 | C6: =-'Working Capital'!C9 -> 3153.4272 | D6: =-'Working Capital'!D9 -> 1938.3664 | E6: =-'Working Capital'!E9 -> 2014.2512 | F6: =-'Working Capital'!F9 -> 2082.9321
A7: ='Historical FS'!A32 -> Operating CF | B7: =B4+B5+B6 -> 401393 | C7: =C4+C5+C6 -> 516405.46 | D7: =D4+D5+D6 -> 735483.59 | E7: =E4+E5+E6 -> 992015.47 | F7: =F4+F5+F6 -> 1288486.7
A8: ='Historical FS'!A33 -> Capex | B8: =-Capex!B11 -> -100000 | C8: =-Capex!C11 -> -100000 | D8: =-Capex!D11 -> -100000 | E8: =-Capex!E11 -> -100000 | F8: =-Capex!F11 -> -100000
A9: ='Historical FS'!A34 -> Debt Movement | B9: =500000-Debt!B18 -> 380000 | C9: =-Debt!C18 -> -120000 | D9: =-Debt!D18 -> -120000 | E9: =-Debt!E18 -> -120000 | F9: =-Debt!F18 -> -100000
A10: ='Historical FS'!A35 -> Owner Contribution | B10: =Equity!B5-Equity!B7 -> -60059.4 | C10: =Equity!C5-Equity!C7 -> -92100.407 | D10: =Equity!D5-Equity!D7 -> -135214.05 | E10: =Equity!E5-Equity!E7 -> -185654.74 | F10: =Equity!F5-Equity!F7 -> -244169.79
A11: ='Historical FS'!A36 -> Net Cash Change | B11: =B7+B8+B9+B10 -> 621333.6 | C11: =C7+C8+C9+C10 -> 204305.06 | D11: =D7+D8+D9+D10 -> 380269.55 | E11: =E7+E8+E9+E10 -> 586360.73 | F11: =F7+F8+F9+F10 -> 844316.86

Sheet Historical FS
A1: Historical Financial Statements
A3: Line Item | B3: FY2022 | C3: FY2023 | D3: FY2024
A4: INCOME STATEMENT
A5: Revenue | B5: 1200000 | C5: 1450000 | D5: 1680000
A6: COGS | B6: -420000 | C6: -500000 | D6: -575000
A7: Gross Profit | B7: =B5+B6 -> 780000 | C7: =C5+C6 -> 950000 | D7: =D5+D6 -> 1105000
A8: Operating Expenses | B8: -420000 | C8: -485000 | D8: -560000
A9: EBITDA | B9: =B7+B8 -> 360000 | C9: =C7+C8 -> 465000 | D9: =D7+D8 -> 545000
A10: Depreciation | B10: -30000 | C10: -35000 | D10: -40000
A11: EBIT | B11: =B9+B10 -> 330000 | C11: =C9+C10 -> 430000 | D11: =D9+D10 -> 505000
A12: Interest | B12: -12000 | C12: -10000 | D12: -8000
A13: PBT | B13: =B11+B12 -> 318000 | C13: =C11+C12 -> 420000 | D13: =D11+D12 -> 497000
A14: Tax | B14: -79500 | C14: -105000 | D14: -124000
A15: Net Income | B15: =B13+B14 -> 238500 | C15: =C13+C14 -> 315000 | D15: =D13+D14 -> 373000
A17: BALANCE SHEET
A18: Cash | B18: 90000 | C18: 120000 | D18: 170000
A19: AR | B19: 15000 | C19: 18000 | D19: 22000
A20: Inventory | B20: 25000 | C20: 28000 | D20: 32000
A21: Net PPE | B21: 250000 | C21: 315000 | D21: 375000
A22: Total Assets | B22: =SUM(B18:B21) -> 380000 | C22: =SUM(C18:C21) -> 481000 | D22: =SUM(D18:D21) -> 599000
A23: AP | B23: 18000 | C23: 22000 | D23: 26000
A24: Debt | B24: 120000 | C24: 100000 | D24: 80000
A25: Owner Equity | B25: 242000 | C25: 359000 | D25: 493000
A26: Total L+E | B26: =SUM(B23:B25) -> 380000 | C26: =SUM(C23:C25) -> 481000 | D26: =SUM(D23:D25) -> 599000
A28: CASH FLOW
A29: Net Income | B29: =B15 -> 238500 | C29: =C15 -> 315000 | D29: =D15 -> 373000
A30: Depreciation | B30: 30000 | C30: 35000 | D30: 40000
A31: Working Capital Change | B31: -5000 | C31: -4000 | D31: -6000
A32: Operating CF | B32: =SUM(B29:B31) -> 263500 | C32: =SUM(C29:C31) -> 346000 | D32: =SUM(D29:D31) -> 407000
A33: Capex | B33: -100000 | C33: -100000 | D33: -100000
A34: Debt Movement | B34: 20000 | C34: -20000 | D34: -20000
A35: Owner Contribution | B35: 50000 | C35: 0 | D35: 0
A36: Net Cash Change | B36: =SUM(B32:B35) -> 233500 | C36: =SUM(C32:C35) -> 226000 | D36: =SUM(D32:D35) -> 287000

Sheet CVP Analysis
A2: Cost-Volume-Profit Analysis for FY25
B4: Volume | C4: Base Case | D4: Worst Case
C5: 74817.894 | D5: =IF(D4="Best Case",C5*(1+C19),IF(D4="Worst Case",C5*(1+D19),)) -> 67336.105
C6: (Enter volume here) | D6: (Select Case here)
B7: Particulars | C7: FY25 | D7: =D4 -> Worst Case
B8: Selling price per unit | C8: =75 -> 75 | D8: =IF(D7="Best Case",C8*(1+C18),IF(D7="Worst Case",C8*(1+D18),)) -> 71.25
B9: Variable cost per unit | C9: ='COGS Schedule'!B13 -> 24.48 | D9: =IF(D4="Best Case",C9*(1+C20),IF(D4="Worst Case",C9*(1+D20),)) -> 26.4384
B10: Contribution per unit | C10: =C8-C9 -> 50.52 | D10: =D8-D9 -> 44.8116
B11: Total Contribution | C11: =C10*C5 -> 3779800 | D11: =D10*D5 -> 3017438.6
B12: Fixed Cost | C12: ='Operating Expenses'!B15+Payroll!D10 -> 2779800 | D12: =IF(D7="Best Case",C12*(1+C21),IF(D7="Worst Case",C12*(1+D21),)) -> 2918790
B13: Profit | C13: =C11-C12 -> 1000000 | D13: =D11-D12 -> 98648.581
B15: Scenario Analysis
B17: Assumption | C17: Best | D17: Worst
B18: Selling price growth | C18: 0.05 | D18: -0.05
B19: Volume Growth | C19: 0.1 | D19: -0.1
B20: VC Growth | C20: -0.02 | D20: 0.08
B21: FC Growth | C21: 0 | D21: 0.05

Sheet Revenue Schedule
A1: Revenue Schedule
A3: Line Item | B3: FY25 | C3: FY26 | D3: FY27 | E3: FY28 | F3: FY29
A4: Customer per year | B4: =Assumptions!C9*Assumptions!C14 -> 64800 | C4: =B4*1.08 -> 69984 | D4: =C4*1.08 -> 75582.72 | E4: =D4*1.08 -> 81629.338 | F4: =E4*1.08 -> 88159.685
A5: Average bill | B5: =Assumptions!C11 -> 75 | C5: =B5*1.04 -> 78 | D5: =C5*1.04 -> 81.12 | E5: =D5*1.04 -> 84.3648 | F5: =E5*1.04 -> 87.739392
A6: Revenue | B6: =B4*B5 -> 4860000 | C6: =C4*C5 -> 5458752 | D6: =D4*D5 -> 6131270.2 | E6: =E4*E5 -> 6886642.7 | F6: =F4*F5 -> 7735077.1

Sheet COGS Schedule
A1: Cost of Goods Sold
A3: Component | B3: FY25 | C3: FY26 | D3: FY27 | E3: FY28 | F3: FY29
A4: =Assumptions!B16 -> Tea Powder/Customer | B4: =Assumptions!C16 -> 4 | C4: =B4*1.04 -> 4.16 | D4: =C4*1.02 -> 4.2432 | E4: =D4*1.02 -> 4.328064 | F4: =E4*1.02 -> 4.4146253
A5: =Assumptions!B17 -> Milk/Customer | B5: =Assumptions!C17 -> 8 | C5: =B5*1.04 -> 8.32 | D5: =C5*1.02 -> 8.4864 | E5: =D5*1.02 -> 8.656128 | F5: =E5*1.02 -> 8.8292506
A6: =Assumptions!B18 -> Sugar/Customer | B6: =Assumptions!C18 -> 2 | C6: =B6*1.04 -> 2.08 | D6: =C6*1.02 -> 2.1216 | E6: =D6*1.02 -> 2.164032 | F6: =E6*1.02 -> 2.2073126
A7: =Assumptions!B19 -> Spices/Customer | B7: =Assumptions!C19 -> 2 | C7: =B7*1.04 -> 2.08 | D7: =C7*1.02 -> 2.1216 | E7: =D7*1.02 -> 2.164032 | F7: =E7*1.02 -> 2.2073126
A8: =Assumptions!B20 -> Packaging/Customer | B8: =Assumptions!C20 -> 3 | C8: =B8*1.04 -> 3.12 | D8: =C8*1.02 -> 3.1824 | E8: =D8*1.02 -> 3.246048 | F8: =E8*1.02 -> 3.310969
A9: =Assumptions!B21 -> Snacks Ingredients/Customer | B9: =Assumptions!C21 -> 5 | C9: =B9*1.04 -> 5.2 | D9: =C9*1.02 -> 5.304 | E9: =D9*1.02 -> 5.41008 | F9: =E9*1.02 -> 5.5182816
A10: Sub Total | B10: =SUM(B4:B9) -> 24 | C10: =B10*1.04 -> 24.96 | D10: =C10*1.02 -> 25.4592 | E10: =D10*1.02 -> 25.968384 | F10: =E10*1.02 -> 26.487752
A11: =Assumptions!B22 -> Wastage (%) | B11: =Assumptions!C22 -> 2% | C11: =B11 -> 2% | D11: =C11 -> 2% | E11: =D11 -> 2% | F11: =E11 -> 2%
A12: Wastage | B12: =B10*B11 -> 0.48 | C12: =C10*C11 -> 0.4992 | D12: =D10*D11 -> 0.509184 | E12: =E10*E11 -> 0.51936768 | F12: =F10*F11 -> 0.52975503
A13: Total COGS per customer | B13: =B10+B12 -> 24.48 | C13: =C10+C12 -> 25.4592 | D13: =D10+D12 -> 25.968384 | E13: =E10+E12 -> 26.487752 | F13: =F10+F12 -> 27.017507
A14: No of Customers | B14: ='Revenue Schedule'!B4 -> 64800 | C14: ='Revenue Schedule'!C4 -> 69984 | D14: ='Revenue Schedule'!D4 -> 75582.72 | E14: ='Revenue Schedule'!E4 -> 81629.338 | F14: ='Revenue Schedule'!F4 -> 88159.685
A15: COGS | B15: =B14*B13 -> 1586304 | C15: =C14*C13 -> 1781736.7 | D15: =D14*D13 -> 1962761.1 | E15: =E14*E13 -> 2162177.6 | F15: =F14*F13 -> 2381854.9

Sheet Operating Expenses
A1: Operating Expenses
A3: Expense | B3: FY25 | C3: FY26 | D3: FY27 | E3: FY28 | F3: FY29
A4: =Assumptions!B37 -> Annual Rent | B4: =Assumptions!C37 -> 600000 | C4: =B4*1.05 -> 630000 | D4: =C4*1.05 -> 661500 | E4: =D4*1.05 -> 694575 | F4: =E4*1.05 -> 729303.75
A5: =Assumptions!B38 -> Electricity | B5: =Assumptions!C38 -> 200000 | C5: =B5*1.05 -> 210000 | D5: =C5*1.05 -> 220500 | E5: =D5*1.05 -> 231525 | F5: =E5*1.05 -> 243101.25
A6: =Assumptions!B39 -> LPG | B6: =Assumptions!C39 -> 60000 | C6: =B6*1.05 -> 63000 | D6: =C6*1.05 -> 66150 | E6: =D6*1.05 -> 69457.5 | F6: =E6*1.05 -> 72930.375
A7: =Assumptions!B40 -> Water | B7: =Assumptions!C40 -> 36000 | C7: =B7*1.05 -> 37800 | D7: =C7*1.05 -> 39690 | E7: =D7*1.05 -> 41674.5 | F7: =E7*1.05 -> 43758.225
A8: =Assumptions!B41 -> Internet | B8: =Assumptions!C41 -> 18000 | C8: =B8*1.05 -> 18900 | D8: =C8*1.05 -> 19845 | E8: =D8*1.05 -> 20837.25 | F8: =E8*1.05 -> 21879.112
A9: =Assumptions!B42 -> Marketing | B9: =3%*'Revenue Schedule'!B6 -> 145800 | C9: =3%*'Revenue Schedule'!C6 -> 163762.56 | D9: =3%*'Revenue Schedule'!D6 -> 183938.11 | E9: =3%*'Revenue Schedule'!E6 -> 206599.28 | F9: =3%*'Revenue Schedule'!F6 -> 232052.31
A10: =Assumptions!B43 -> Repairs | B10: =Assumptions!C43 -> 50000 | C10: =B10*1.05 -> 52500 | D10: =C10*1.05 -> 55125 | E10: =D10*1.05 -> 57881.25 | F10: =E10*1.05 -> 60775.312
A11: =Assumptions!B44 -> Insurance | B11: =Assumptions!C44 -> 24000 | C11: =B11*1.05 -> 25200 | D11: =C11*1.05 -> 26460 | E11: =D11*1.05 -> 27783 | F11: =E11*1.05 -> 29172.15
A12: =Assumptions!B45 -> Office Expense | B12: =Assumptions!C45 -> 36000 | C12: =B12*1.05 -> 37800 | D12: =C12*1.05 -> 39690 | E12: =D12*1.05 -> 41674.5 | F12: =E12*1.05 -> 43758.225
A13: =Assumptions!B46 -> Miscellaneous | B13: =Assumptions!C46 -> 50000 | C13: =B13*1.05 -> 52500 | D13: =C13*1.05 -> 55125 | E13: =D13*1.05 -> 57881.25 | F13: =E13*1.05 -> 60775.312
A15: Operating Expenses | B15: =SUM(B4:B14) -> 1219800 | C15: =SUM(C4:C14) -> 1291462.6 | D15: =SUM(D4:D14) -> 1368023.1 | E15: =SUM(E4:E14) -> 1449888.5 | F15: =SUM(F4:F14) -> 1537506

Sheet Payroll
A1: Payroll
A3: Position | B3: Headcount | C3: Monthly Salary | D3: FY25 | E3: FY26 | F3: FY27 | G3: FY28 | H3: FY29
A4: =Assumptions!B25 -> Manager Salary | B4: =Assumptions!C30 -> 1 | C4: =Assumptions!C25 -> 30000 | D4: =C4*B4*12 -> 360000 | E4: =D4*1.08 -> 388800 | F4: =E4*1.08 -> 419904 | G4: =F4*1.08 -> 453496.32 | H4: =G4*1.08 -> 489776.03
A5: =Assumptions!B26 -> Cashier Salary | B5: =Assumptions!C31 -> 1 | C5: =Assumptions!C26 -> 18000 | D5: =C5*B5*12 -> 216000 | E5: =D5*1.08 -> 233280 | F5: =E5*1.08 -> 251942.4 | G5: =F5*1.08 -> 272097.79 | H5: =G5*1.08 -> 293865.62
A6: =Assumptions!B27 -> Tea Master Salary | B6: =Assumptions!C32 -> 2 | C6: =Assumptions!C27 -> 20000 | D6: =C6*B6*12 -> 480000 | E6: =D6*1.08 -> 518400 | F6: =E6*1.08 -> 559872 | G6: =F6*1.08 -> 604661.76 | H6: =G6*1.08 -> 653034.7
A7: =Assumptions!B28 -> Helper Salary | B7: =Assumptions!C33 -> 2 | C7: =Assumptions!C28 -> 15000 | D7: =C7*B7*12 -> 360000 | E7: =D7*1.08 -> 388800 | F7: =E7*1.08 -> 419904 | G7: =F7*1.08 -> 453496.32 | H7: =G7*1.08 -> 489776.03
A8: =Assumptions!B29 -> Cleaner Salary | B8: =Assumptions!C34 -> 1 | C8: =Assumptions!C29 -> 12000 | D8: =C8*B8*12 -> 144000 | E8: =D8*1.08 -> 155520 | F8: =E8*1.08 -> 167961.6 | G8: =F8*1.08 -> 181398.53 | H8: =G8*1.08 -> 195910.41
A10: Payroll | D10: =SUM(D4:D9) -> 1560000 | E10: =SUM(E4:E9) -> 1684800 | F10: =SUM(F4:F9) -> 1819584 | G10: =SUM(G4:G9) -> 1965150.7 | H10: =SUM(H4:H9) -> 2122362.8

Sheet Working Capital
A1: Working Capital and Changes
A3: Metric | B3: FY25 | C3: FY26 | D3: FY27 | E3: FY28 | F3: FY29
A4: Accounts Receivable | B4: ='Revenue Schedule'!B6*(Assumptions!$C$49/360) -> 40500 | C4: ='Revenue Schedule'!C6*(Assumptions!$C$49/360) -> 45489.6 | D4: ='Revenue Schedule'!D6*(Assumptions!$C$49/360) -> 51093.919 | E4: ='Revenue Schedule'!E6*(Assumptions!$C$49/360) -> 57388.69 | F4: ='Revenue Schedule'!F6*(Assumptions!$C$49/360) -> 64458.976
A5: Inventory | B5: ='COGS Schedule'!B15*(Assumptions!$C$50/360) -> 66096 | C5: ='COGS Schedule'!C15*(Assumptions!$C$50/360) -> 74239.027 | D5: ='COGS Schedule'!D15*(Assumptions!$C$50/360) -> 81781.712 | E5: ='COGS Schedule'!E15*(Assumptions!$C$50/360) -> 90090.734 | F5: ='COGS Schedule'!F15*(Assumptions!$C$50/360) -> 99243.953
A6: Accounts Payable | B6: ='COGS Schedule'!B15*(Assumptions!$C$51/360) -> 132192 | C6: ='COGS Schedule'!C15*(Assumptions!$C$51/360) -> 148478.05 | D6: ='COGS Schedule'!D15*(Assumptions!$C$51/360) -> 163563.42 | E6: ='COGS Schedule'!E15*(Assumptions!$C$51/360) -> 180181.47 | F6: ='COGS Schedule'!F15*(Assumptions!$C$51/360) -> 198487.91
A8: Working Capital | B8: =SUM(B4:B5)-B6 -> -25596 | C8: =SUM(C4:C5)-C6 -> -28749.427 | D8: =SUM(D4:D5)-D6 -> -30687.794 | E8: =SUM(E4:E5)-E6 -> -32702.045 | F8: =SUM(F4:F5)-F6 -> -34784.977
A9: Change in WC | B9: =B8-('Historical FS'!D19+'Historical FS'!D20-'Historical FS'!D23) -> -53596 | C9: =C8-B8 -> -3153.4272 | D9: =D8-C8 -> -1938.3664 | E9: =E8-D8 -> -2014.2512 | F9: =F8-E8 -> -2082.9321

Sheet Capex
A1: Capital Expenditure
A3: Capex Item | B3: FY25 | C3: FY26 | D3: FY27 | E3: FY28 | F3: FY29
A4: Tea Brewing Equipment | B4: 30000 | C4: 15000 | D4: 20000 | E4: 15000 | F4: 20000
A5: Kitchen Equipment | B5: 20000 | C5: 20000 | D5: 15000 | E5: 20000 | F5: 15000
A6: Furniture & Fixtures | B6: 15000 | C6: 20000 | D6: 20000 | E6: 15000 | F6: 20000
A7: Interior Improvements | B7: 10000 | C7: 15000 | D7: 10000 | E7: 15000 | F7: 10000
A8: Air Conditioner & Electrical | B8: 10000 | C8: 10000 | D8: 15000 | E8: 10000 | F8: 15000
A9: POS System / IT / Billing | B9: 10000 | C9: 10000 | D9: 10000 | E9: 15000 | F9: 10000
A10: CCTV / Misc. Equipment | B10: 5000 | C10: 10000 | D10: 10000 | E10: 10000 | F10: 10000
A11: Total Capex | B11: =SUM(B4:B10) -> 100000 | C11: =SUM(C4:C10) -> 100000 | D11: =SUM(D4:D10) -> 100000 | E11: =SUM(E4:E10) -> 100000 | F11: =SUM(F4:F10) -> 100000

Sheet Depreciation
A1: Fixed Assets Schedule
A3: Year | B3: FY25 | C3: FY26 | D3: FY27 | E3: FY28 | F3: FY29
A4: Opening | B4: 375000 | C4: =B7 -> 427500 | D4: =C7 -> 474750 | E4: =D7 -> 517275 | F4: =E7 -> 555547.5
A5: Addition | B5: =Capex!B11 -> 100000 | C5: =Capex!C11 -> 100000 | D5: =Capex!D11 -> 100000 | E5: =Capex!E11 -> 100000 | F5: =Capex!F11 -> 100000
A6: Depreciation | B6: =(B4+B5)/10 -> 47500 | C6: =(C4+C5)/10 -> 52750 | D6: =(D4+D5)/10 -> 57475 | E6: =(E4+E5)/10 -> 61727.5 | F6: =(F4+F5)/10 -> 65554.75
A7: Closing | B7: =B4+B5-B6 -> 427500 | C7: =C4+C5-C6 -> 474750 | D7: =D4+D5-D6 -> 517275 | E7: =E4+E5-E6 -> 555547.5 | F7: =F4+F5-F6 -> 589992.75

Sheet Debt
A1: Debt Schedule
A3: Particulars | B3: FY25 | C3: FY26 | D3: FY27 | E3: FY28 | F3: FY29
A4: Debt 1
A5: Opening | B5: ='Historical FS'!D24 -> 80000 | C5: =B7 -> 60000 | D5: =C7 -> 40000 | E5: =D7 -> 20000
A6: Principal payment | B6: 20000 | C6: 20000 | D6: 20000 | E6: 20000
A7: Net | B7: =B5-B6 -> 60000 | C7: =C5-C6 -> 40000 | D7: =D5-D6 -> 20000 | E7: =E5-E6 -> 0
A8: Interest Payment | B8: =B7*10% -> 6000 | C8: =C7*10% -> 4000 | D8: =D7*10% -> 2000 | E8: =E7*10% -> 0
A10: Debt 2
A11: Opening | B11: 500000 | C11: =B13 -> 400000 | D11: =C13 -> 300000 | E11: =D13 -> 200000 | F11: =E13 -> 100000
A12: Principal payment | B12: 100000 | C12: 100000 | D12: 100000 | E12: 100000 | F12: 100000
A13: Net | B13: =B11-B12 -> 400000 | C13: =C11-C12 -> 300000 | D13: =D11-D12 -> 200000 | E13: =E11-E12 -> 100000 | F13: =F11-F12 -> 0
A14: Interest Payment | B14: =B13*10% -> 40000 | C14: =C13*10% -> 30000 | D14: =D13*10% -> 20000 | E14: =E13*10% -> 10000 | F14: =F13*10% -> 0
A16: Interest | B16: =B8+B14 -> 46000 | C16: =C8+C14 -> 34000 | D16: =D8+D14 -> 22000 | E16: =E8+E14 -> 10000 | F16: =F8+F14 -> 0
A17: Debt | B17: =B13+B7 -> 460000 | C17: =C13+C7 -> 340000 | D17: =D13+D7 -> 220000 | E17: =E13+E7 -> 100000 | F17: =F13+F7 -> 0
A18: Principal Paid | B18: =B12+B6 -> 120000 | C18: =C12+C6 -> 120000 | D18: =D12+D6 -> 120000 | E18: =E12+E6 -> 120000 | F18: =F12+F6 -> 100000

Sheet Equity
A1: Equity Schedule
A3: Item | B3: FY25 | C3: FY26 | D3: FY27 | E3: FY28 | F3: FY29
A4: Opening Equity | B4: ='Historical FS'!D25 -> 493000 | C4: =B8 -> 733237.6 | D4: =C8 -> 1101639.2 | E4: =D8 -> 1642495.4 | F4: =E8 -> 2385114.4
A5: + Additional Capital
A6: + Net Income | B6: ='Forecast IS'!B24 -> 300297 | C6: ='Forecast IS'!C24 -> 460502.04 | D6: ='Forecast IS'!D24 -> 676070.23 | E6: ='Forecast IS'!E24 -> 928273.72 | F6: ='Forecast IS'!F24 -> 1220849
A7: - Dividend | B7: =B6*20% -> 60059.4 | C7: =C6*20% -> 92100.407 | D7: =D6*20% -> 135214.05 | E7: =E6*20% -> 185654.74 | F7: =F6*20% -> 244169.79
A8: Closing Equity | B8: =B4+B5+B6-B7 -> 733237.6 | C8: =C4+C5+C6-C7 -> 1101639.2 | D8: =D4+D5+D6-D7 -> 1642495.4 | E8: =E4+E5+E6-E7 -> 2385114.4 | F8: =F4+F5+F6-F7 -> 3361793.6

Sheet DCF Valuation
A1: DCF Valuation
A3: Item | B3: FY25 | C3: FY26 | D3: FY27 | E3: FY28 | F3: FY29 | G3: FY30 (TV)
A4: Revenue | B4: ='Revenue Schedule'!B6 -> 4860000 | C4: ='Revenue Schedule'!C6 -> 5458752 | D4: ='Revenue Schedule'!D6 -> 6131270.2 | E4: ='Revenue Schedule'!E6 -> 6886642.7 | F4: ='Revenue Schedule'!F6 -> 7735077.1 | G4: 0
A5: EBIT | B5: ='Forecast IS'!B16 -> 446396 | C5: ='Forecast IS'!C16 -> 648002.72 | D5: ='Forecast IS'!D16 -> 923426.97 | E5: ='Forecast IS'!E16 -> 1247698.3 | F5: ='Forecast IS'!F16 -> 1627798.6 | G5: 0
A6: Tax | B6: =B5*25% -> 111599 | C6: =C5*25% -> 162000.68 | D6: =D5*25% -> 230856.74 | E6: =E5*25% -> 311924.57 | F6: =F5*25% -> 406949.66 | G6: 0
A7: NOPAT | B7: =B5-B6 -> 334797 | C7: =C5-C6 -> 486002.04 | D7: =D5-D6 -> 692570.23 | E7: =E5-E6 -> 935773.72 | F7: =F5-F6 -> 1220849 | G7: 0
A8: + Depreciation | B8: ='Forecast IS'!B14 -> 47500 | C8: ='Forecast IS'!C14 -> 52750 | D8: ='Forecast IS'!D14 -> 57475 | E8: ='Forecast IS'!E14 -> 61727.5 | F8: ='Forecast IS'!F14 -> 65554.75 | G8: 0
A9: - Capex | B9: =-Capex!B4 -> -30000 | C9: =-Capex!C4 -> -15000 | D9: =-Capex!D4 -> -20000 | E9: =-Capex!E4 -> -15000 | F9: =-Capex!F4 -> -20000 | G9: 0
A10: - Change in NWC | B10: =-'Working Capital'!B9 -> 53596 | C10: =-'Working Capital'!C9 -> 3153.4272 | D10: =-'Working Capital'!D9 -> 1938.3664 | E10: =-'Working Capital'!E9 -> 2014.2512 | F10: =-'Working Capital'!F9 -> 2082.9321 | G10: 0
A11: FCFF | B11: =B7+B8+B9+B10 -> 405893 | C11: =C7+C8+C9+C10 -> 526905.46 | D11: =D7+D8+D9+D10 -> 731983.59 | E11: =E7+E8+E9+E10 -> 984515.47 | F11: =F7+F8+F9+F10 -> 1268486.7 | G11: =F11*1.04/8% -> 16490327
A12: Discount Factor | B12: =1/(1.12)^B13 -> 0.89285714 | C12: =1/(1.12)^C13 -> 0.79719388 | D12: =1/(1.12)^D13 -> 0.71178025 | E12: =1/(1.12)^E13 -> 0.63551808 | F12: =1/(1.12)^F13 -> 0.56742686 | G12: =1/(1.12)^G13 -> 0.50663112
A13: Year | B13: 1 | C13: 2 | D13: 3 | E13: 4 | F13: 5 | G13: 6
A14: Present Value | B14: =B11*B12 -> 362404.46 | C14: =C11*C12 -> 420045.81 | D14: =D11*D12 -> 521011.46 | E14: =E11*E12 -> 625677.38 | F14: =F11*F12 -> 719773.39 | G14: =G11*G12 -> 8354512.6
